Workbook

Sheet hotels IST
A1: Collection | B1: hotels "IST"
A2: Remarks | B2: Hotels
A3: Date / Update | B3: 46203
A5: Special field type | B5: field_key Directus | C5: data_type | D5: interface (characters max) | E5: Relation (Sub-Collection) | F5: Label DE | G5: Label GB | H5: Label NL | I5: Info-Text (below the field) | K5: Yes / No | L5: Naming Translation-Collection
A6: Field hidden | B6: id | C6: uuid | D6: input | K6: No
A7: Field hidden | B7: sort | C7: integer | D7: input | K7: No
A8: Field hidden | B8: user_created | C8: uuid | D8: select-dropdown-m2o | E8: directus_users | K8: No
A9: Field hidden | B9: date_created | C9: timestamp | D9: datetime | K9: No
A10: Above Tabs | B10: header | C10: alias | D10: header | K10: No
A11: Tab-Navigation | B11: hotel_tabs | C11: alias | D11: group-tabs | K11: No
A12: Tab | B12: master_data_group | C12: alias | D12: group-raw | F12: Stammdaten | G12: Master Data | H12: Stamgegevens | K12: No
A13: Block | B13: accordion-obvxyf | C13: alias | D13: group-raw | K13: No
A14: Section | B14: travel_id_group | C14: alias | D14: group-detail | F14: Name & Veröffentlichung | G14: Name & Publication | H14: Naam & Publicatie | K14: No
B15: name | C15: string | D15: input | F15: Hotelname | G15: Hotel Name | H15: Hotelnaam | K15: No
B16: season | C16: integer | D16: select-dropdown-m2o | E16: seasons | F16: Saisonzeit | G16: Season | H16: Seizoen | K16: No
A17: Field hidden | B17: object_info | C17: string | D17: input | K17: No
B18: object_id | C18: integer | D18: input | F18: Objekt-ID | G18: Object-ID | H18: Object-ID | I18: $t:hotels_object_id_note | K18: No
B19: status_primarix | C19: string | D19: select-dropdown | F19: Status Primarix | G19: Status Primarix | H19: Status Primarix | K19: No
B20: internal_remarks | C20: text | D20: input-multiline | F20: Interne Hinweise | G20: Internal Remarks | H20: Interne opmerking | I20: $t:hotel_internal_remarks_note | K20: No
A21: Field hidden | B21: date_updated | C21: timestamp | D21: datetime | F21: Zuletzt aktualisiert | G21: Last Update | H21: Laatste update | K21: No
A22: Field hidden | B22: user_updated | C22: uuid | D22: select-dropdown-m2o | E22: directus_users | F22: von | G22: by | H22: door | K22: No
A23: Section | B23: partner_group | C23: alias | D23: group-detail | F23: Partner Filter | G23: Partner Filter | H23: Partner Filter | K23: No
B24: partner_type | C24: string | D24: select-radio | F24: Auswahl BOTG Partner | G24: Choice BOTG Partner | K24: No
B25: partner | C25: alias | D25: list-m2m | E25: partner | F25: Ausgewählte Partner | G25: Chosen Partner(s) | K25: No
A26: Block | B26: main_group | C26: alias | D26: group-raw | K26: No
A27: Section | B27: master_data | C27: alias | D27: group-detail | F27: Adresse Hotel | G27: Address Hotel | H27: Adres Hotel | K27: No
B28: hotel_group | C28: uuid | D28: select-dropdown-m2o | E28: hotel_group | F28: Hotelkette | G28: Hotel Group | H28: Hotelketen | I28: $t:hotels_hotel_group_note | K28: No
B29: street | C29: string | D29: input | F29: Straße | G29: Street | H29: Straat | K29: No
B30: street_number | C30: string | D30: input | F30: Hausnummer | G30: Street Number | H30: Huisnummer | K30: No
B31: zip_code | C31: string | D31: input | F31: PLZ | G31: Postal Code | H31: Postcode | K31: No
B32: place | C32: integer | D32: cascading-individual-select | E32: places | F32: Ort | G32: City/Town | H32: Plaats | I32: $t:hotels_place | K32: No
B33: location_tour32 | C33: integer | D33: cascading-individual-select | E33: locations_tour32 | F33: Suchort (Tour User only) | G33: Search Location (Tour User only) | H33: Zoeklocatie (Tour User only) | K33: No
B34: state | C34: integer | D34: cascading-individual-select | E34: states | F34: Zustand | G34: State | H34: Staat | K34: No
B35: region | C35: integer | D35: cascading-individual-select | E35: regions | G35: Region | H35: Regio | K35: No
B36: country | C36: integer | D36: cascading-individual-select | E36: countries | F36: Land | G36: Country | H36: Land | I36: $t:hotels_country | K36: No
B37: phone_general | C37: string | D37: input | F37: Telefon (allgemein) | G37: Phone (general) | H37: Telefoon (algemeen) | K37: No
B38: phone_ah | C38: string | D38: input | F38: Telefon (after hours) | G38: Phone (after hours) | H38: Telefoon (na kantooruren) | K38: No
B39: email_general | C39: string | D39: input | F39: Email (allgemein) | G39: E-mail (general) | H39: Email (algemeen) | K39: No
B40: website | C40: string | D40: input | F40: Webseite | G40: Web Site | H40: Homepage | K40: No
A41: Block | B41: partner_raw_group | C41: alias | D41: group-raw | G41: Partner Filter | K41: No
...

Sheet hotels SOLL
A1: Collection | B1: hotels IDEAL STATE
A2: Remarks | B2: Hotels
A3: Date / Update | B3: 46203
A4: Legend | B4: Checked | C4: Changes | D4: Analysis done | E4: Analysis tbd
A6: Details for Directus Set-up | K6: Translatable? | N6: Import Details "hotels" | U6: Remarks / Comments | X6: Legacy | Y6: Stakeholder Notes
A7: Special field type | B7: field_key Directus | C7: data_type | D7: interface (characters max) | E7: Relation (Sub-Collection) | F7: Label DE | G7: Label GB | H7: Label NL | I7: Info-Text (below the field) | K7: Yes / No | L7: Naming Translation-Collection | M7: Δ / Hinweis (IST↔SOLL) | N7: fieldid Primarix | O7: parent table | U7: Remarks for DEV (field set-up and Import) | V7: Remarks + Tasks internal | X7: tbd after import | Y7: TOPS Bernd | Z7: TOPs Birgit | AA7: Notes Client
A9: Above Tabs | B9: sell_prices_status | C9: string | D9: select-dropdown | F9: Verkaufspreis-Status | G9: Sell Prices Status | H9: Verkoopprijsstatus | I9: Tracks async sell price calculation state | K9: No | U9: hidden, root sync field
A10: Above Tabs | B10: sell_prices_updated_at | C10: timestamp | D10: datetime | F10: Aktualisiert am | G10: Sell Prices Updated At | H10: Bijgewerkt op | I10: Last successful sell price calculation | K10: No | U10: hidden, root sync field
A11: Tab-Navigation | B11: ui_tabs | C11: alias | D11: tabs | F11: - | G11: - | H11: -
A13: Tab | B13: tab_master_data | C13: alias | D13: group-raw | F13: Stammdaten | G13: Master Data | H13: Stamgegevens
A14: Block | B14: block_publication | C14: alias | D14: group-raw | F14: - | G14: - | H14: -
A15: Section (open) | B15: section_id_status | C15: alias | D15: group-detail | F15: Status & Veröffentlichung | G15: Status & Publication | H15: Status & publicatie
B16: object_id | C16: integer | D16: numerical | F16: Objekt-ID | G16: Object-ID | H16: Object-ID | I16: Automatically set. | K16: No | N16: oid | O16: hotels
B17: object_info_primarix | C17: string | D17: text input | F17: Objekt Titel Primarix | G17: Object Title Primarix | H17: Objecttitel Primarix | K17: No | M17: IST: object_info (umbenennen) | N17: object_info | U17: Non editable field
B18: season | C18: integer | D18: many to one | E18: seasons | F18: Saison-Gültigkeit | G18: Season Validity | H18: Seizoengeldigheid | K18: No | N18: season | U18: Transformed value from "object info": "25_" = "2025"
B19: status_primarix | C19: string | D19: select-dropdown | F19: Status Primarix | G19: Status Primarix | H19: Status Primarix | K19: No | N19: status (?) | O19: ?
B20: internal_remarks | C20: text | D20: text area | F20: Interne Hinweise | G20: Internal Remarks | H20: Interne opmerking | I20: Internal Remarks from Primarix. - Please consider for the future the "Comments"-Feature (Icon on right side). | K20: No | N20: field_131_1 | O20: hotels | U20: IMPORTANT: The field is in future NOT translatable. Within the import you need all "internal_remarks" into this field (also from other languages).
B21: date_updated | C21: dateTime | D21: date | F21: Zuletzt aktualisiert | G21: Last Update | H21: Laatste update | K21: No | N21: (?) | U21: Pls show the last update date if possible
B22: user_updated | F22: von | G22: by | H22: door | K22: No | U22: Pls show the last editor if possible (in case information is not available in Primarix show "unknown" or similar)
A24: Section (open) | B24: section_botg_filter | C24: alias | D24: group-detail | F24: BOTG-Firmen-Zuordnung | G24: BOTG Company Assignment | H24: BOTG-bedrijfstoewijzing
B25: partner_visibility | C25: string | D25: radio | K25: No | M25: IST: partner_type (umbenennen); Label bewusst leer (Radio – Info steckt in den Optionen)
B26: partner_selected | C26: integer | D26: many to one | E26: partner | K26: No | M26: IST: partner (umbenennen); E bereinigt; Label bewusst leer (M2O, gekoppelt an das partner_visibility-Radio) | N26: field_1144_1 | O26: hotels
A28: Block | B28: block_contacts | C28: alias | D28: group-raw | F28: - | G28: - | H28: -
A29: Section (open) | B29: section_address | C29: alias | D29: group-detail | F29: Adresse Hotel | G29: Hotel Address | H29: Adres hotel
B30: name_hotel | C30: string | D30: text input | F30: Hotelname | G30: Hotel Name | H30: Hotelnaam | K30: No | M30: IST: name (umbenennen) | N30: field_41_1 | O30: hotels
B31: hotel_group | C31: integer | D31: many to one | E31: hotel_groups | F31: Hotelkette | G31: Hotel Group | H31: Hotelketen | I31: Chose only if the hotel is part of a group. | K31: No | M31: DEV-IST: Collection heißt hotel_group (Singular, Abweichler) → SOLL hotel_groups (C1 Plural); Feld bleibt hotel_group. Directus-Rename = neue Collection + Migration + alte löschen | N31: field_1405_1 | O31: hotels
B32: street | C32: string | D32: text input | F32: Straße | G32: Street | H32: Straat | K32: No | N32: field_26_1 | O32: hotels
B33: street_number | C33: string | D33: text input | F33: Hausnummer | G33: Street Number | H33: Huisnummer | K33: No | N33: field_27_1 | O33: hotels
B34: zip_code | C34: string | D34: text input | F34: PLZ | G34: Postal Code | H34: Postcode | K34: No | N34: field_171_1 | O34: hotels
B35: place | C35: string | D35: auto complete | E35: places | F35: Ort | G35: City / Town | H35: Plaats | I35: Defines further geographical details (country, state, region). | K35: No | N35: field_28_1 | O35: hotels | U35: Please adapt import: Actually this field contains text inputs - these need to be matched to the entry in to the new collection "places"
B36: location_tour32 | C36: integer | D36: many to one | E36: locations_tour32 | F36: Suchort (Tour User only) | G36: Search Location (Tour User only) | H36: Zoeklocatie (Tour User only) | K36: No | N36: field_1342_1 | O36: hotels | U36: Please adapt import: Actually this field contains text inputs - these need to be matched to the entry in to the new collection "locations_tour32"
B37: country | C37: integer | D37: many to one | E37: countries | F37: Land | G37: Country | H37: Land | I37: Defined by "Place" | K37: No | N37: field_1031_1 | O37: hotels | U37: Pls integrate new logic "Geographies".
B38: state | C38: integer | D38: many to one | E38: states | F38: Staat / Bundesland | G38: State / Province | H38: Staat / Provincie | K38: No | N38: field_29_1 | O38: hotels | U38: New logic for geographies
B39: state_short | F39: Bundesland kurz | G39: State code | H39: Provincie kort | K39: No | N39: field_1017_1 | O39: hotels | U39: NOT to be imported!
B40: region | C40: integer | D40: many to one | E40: regions | F40: Region | G40: Region | H40: Regio | K40: No | M40: NL korrigiert: Regio (war „Region" – Brief-Tippfehler); DEV führt bereits Regio. | N40: field_1032_1 | O40: hotels | U40: New logic for geographies
B41: phone_general | C41: string | D41: phone number | F41: Telefon (allgemein) | G41: Phone (general) | H41: Telefoon (algemeen) | K41: No | N41: field_31_1 | O41: hotels | V41: ggf. als "repeater (json)"
B42: phone_after_hours | C42: string | D42: phone number | F42: Telefon (after hours) | G42: Phone (after hours) | H42: Telefoon (na kantooruren) | K42: No | M42: IST: phone_ah (umbenennen) | N42: field_218_1 | O42: hotels
B43: fax_general | D43: - | F43: Fax (allgemein) | G43: Fax (General) | H43: Fax (algemeen) | K43: No | N43: field_32_1 | O43: hotels | U43: NOT to be imported!
B44: email_general | C44: string | D44: mail | F44: Email (allgemein) | G44: E-mail (general) | H44: Email (algemeen) | K44: No | N44: field_42_1 | O44: hotels
B45: website | C45: string | D45: url | F45: Webseite | G45: Web Site | H45: Homepage | K45: No | N45: field_36_1 | O45: hotels
...

Sheet #2 cruises
A1: Collection | B1: cruises
A2: Remarks | B2: Cruises / Kreuzfahrten
A3: Date / Update | B3: 2026-06-29
A4: Legend | B4: Checked | C4: Changes | D4: Analysis done | E4: Analysis tbd
A6: Details for Directus Set-up | K6: Translatable? | N6: Import Details "kreuzfahrten" | U6: Remarks / Comments | X6: Legacy | Y6: Stakeholder Notes
A7: Special field type | B7: field_key Directus | C7: data_type | D7: interface (characters max) | E7: Relation (Sub-Collection) | F7: Label DE | G7: Label GB | H7: Label NL | I7: Info-Text (below the field) | K7: Yes / No | L7: Naming Translation-Collection | N7: fieldid Primarix | O7: parent table | U7: Remarks for DEV (field set-up and Import) | V7: Remarks + Tasks internal | X7: tbd after import | Y7: TOPS Bernd | Z7: TOPs Birgit | AA7: Notes Client
A9: Above Tabs | B9: header | C9: alias | D9: header (presentation) | F9: — | G9: — | H9: — | I9: Page header above the tabs. Shows title + subtitle; no own label. | K9: No | U9: Hidden Standard (hotels): interface "header", special [alias,no-data], group: null. options.title="{{name}}", options.subtitle="{{object_id}} - {{season.season}}". Condition "Hide on create" (id _null -> hidden, clear_hidden_value_on_save).
A10: Above Tabs | B10: sell_prices_status | C10: string | D10: select-dropdown | F10: Verkaufspreis-Status | G10: Sell Prices Status | H10: Verkoopprijsstatus | I10: Tracks async sell price calculation state | K10: No | U10: hidden, root sync field
A11: Above Tabs | B11: sell_prices_updated_at | C11: timestamp | D11: datetime | F11: Aktualisiert am | G11: Sell Prices Updated At | H11: Bijgewerkt op | I11: Last successful sell price calculation | K11: No | U11: hidden, root sync field
A12: Tab-Navigation | B12: ui_tabs | C12: alias | D12: tabs | F12: - | G12: - | H12: -
A14: Tab | B14: tab_master_data | C14: alias | D14: group-raw | F14: Stammdaten | G14: Master Data | H14: Stamgegevens
A15: Block | B15: block_publication | C15: alias | D15: group-raw | F15: - | G15: - | H15: -
A16: Section (open) | B16: section_id_status | C16: alias | D16: group-detail | F16: Status & Veröffentlichung | G16: Status & Publication | H16: Status & publicatie
B17: object_id | C17: integer | D17: integer | E17: numerical | F17: Objekt-ID | G17: Object-ID | H17: Object-ID | I17: Automatically set. | K17: No | N17: oid | O17: kreuzfahrten
B18: object_info_primarix | C18: string | D18: string | E18: text input | F18: Objekt Titel Primarix | G18: Object Title Primarix | H18: Objecttitel Primarix | K18: No | N18: object_info | O18: kreuzfahrten | U18: Non editable field
B19: season | C19: integer | D19: integer | E19: M2O | F19: Saison-Gültigkeit | G19: Season Validity | H19: Seizoengeldigheid | K19: No | N19: season | O19: tours | U19: Transformed value from "object info": "25_" = "2025"
B20: status_primarix | C20: string | D20: select-dropdown | F20: Status Primarix | G20: Status Primarix | H20: Status Primarix | I20: 4 Werte: Draft / Published / Unpublished / Archived (Field-Configs §1.1) | K20: No | N20: status (?) | O20: kreuzfahrten
B21: date_updated | C21: dateTime | D21: date | F21: Zuletzt aktualisiert | G21: Last Update | H21: Laatste update | K21: No | N21: (?) | O21: kreuzfahrten
B22: user_updated | C22: uuid | D22: M2O | E22: directus_users | F22: von | G22: by | H22: door | K22: No | N22: (?) | O22: kreuzfahrten | U22: Pls show the last editor if possible (in case information is not available in Primarix show "unknown" or similar)
A24: Section (open) | B24: section_botg_filter | C24: alias | D24: group-detail | F24: BOTG-Firmen-Zuordnung | G24: BOTG Company Assignment | H24: BOTG-bedrijfstoewijzing
B25: partner_visibility | C25: string | D25: radio | K25: No | L25: hotel
B26: partner_selected | C26: integer | D26: M2O | E26: partner | K26: No | L26: hotel | N26: NEW | O26: tours
A28: Block | B28: block_contacts | C28: alias | D28: group-raw | F28: - | G28: - | H28: -
A29: Section (open) | B29: section_reservation | C29: alias | D29: group-detail | F29: Reservierung | G29: Reservation | H29: Reservering
B30: travel_id_karawane | C30: string | D30: text field | E30: - | F30: Reisenummer | G30: Trip Number | H30: Reisnummer | K30: No | N30: field_677_1 | O30: kreuzfahrten | U30: Import but hide this field.
B31: id_tour32 | C31: string | D31: text field | E31: - | F31: ID Tour32 | G31: ID Tour32 | H31: ID Tour32 | I31: Tour-Angebots-Nr. (falls vorhanden) | K31: No | N31: field_678_1 | O31: kreuzfahrten
A33: Tab | B33: tab_description | C33: alias | D33: group-raw | F33: Beschreibung | G33: Description | H33: Beschrijving
A34: Section (open) | B34: section_classification | C34: alias | D34: group-detail | F34: Klassifizierung | G34: Classification | H34: Indeling
D35: — | F35: Rubrik | N35: field_759_1 | O35: kreuzfahrten | U35: NO Import
B36: countries | C36: alias | D36: M2M | E36: countries | F36: Länder | G36: Countries | H36: Landen | K36: No | N36: field_680_1 | O36: kreuzfahrten | U36: Adapt import: Actually field contains text inputs. Match to entry in new collection. Report missing data separatly!
B37: destinations | C37: alias | D37: M2M | E37: destination | F37: Kontinente | G37: Continents | H37: Continenten | K37: No | N37: field_679_1 | O37: kreuzfahrten | U37: Adapt import: Actually field contains text inputs. Match to entry in new collection. Report missing data separatly!
B38: cruise_types | C38: alias | D38: M2M | E38: cruise_types | F38: Art der Kreuzfahrt | G38: Cruise Type | H38: Cruisetype | K38: No | N38: field_681_1 | O38: kreuzfahrten | U38: see sheet "Field lists Karawane"
B39: real_url | C39: string | D39: text input | F39: Real URL der Reise | G39: Real URL of Trip | H39: Real URL van de reis | K39: No | N39: field_793_1 | O39: kreuzfahrten | U39: Import but hide this field. | V39: Mit TravelUp zu klären.
D40: — | F40: Domainzuordnung | N40: field_682_1 | O40: kreuzfahrten | U40: NO Import
B41: travel_expert | C41: integer | D41: drop down (many to one) | E41: travel_expert | F41: Reiseexperte | G41: Travel Expert | H41: Reisexpert | K41: No | N41: field_1369_1 | O41: kreuzfahrten | U41: NO Import! | V41: Wird für Kreuzfahrten über Website gelöst. In Studienreisen aber erforderlich.
A43: Section (open) | B43: section_descriptions | C43: alias | D43: group-detail | F43: Beschreibung Kreuzfahrt | G43: Cruise Description | H43: Beschrijving cruise
B44: headline | C44: string | D44: text input | F44: Überschrift | G44: Headline | H44: Koptekst | K44: Yes | L44: cruises_descriptions_translations | N44: field_683_1 | O44: kreuzfahrten
B45: subline | C45: string | D45: text input | F45: Untertitel | G45: Subtitle | H45: Ondertitel | K45: Yes | L45: cruises_descriptions_translations | N45: field_684_1 | O45: kreuzfahrten
B46: teaser | C46: text | D46: text area | F46: Einleitung | G46: Introduction | H46: Inleiding | K46: Yes | L46: cruises_descriptions_translations | N46: field_685_1 | O46: kreuzfahrten
B47: ship | C47: text | D47: md-editor | F47: Schiffsbeschreibung (Ihr Schiff) | G47: Ship Description (Your Ship) | H47: Scheepsbeschrijving (Uw schip) | K47: Yes | L47: cruises_descriptions_translations | N47: field_791_1 | O47: kreuzfahrten | U47: Import: Change HTML- to MD-Format
...

Sheet #3 excursions (aka daytrips)
A1: Collection | B1: excursions
A2: Remarks | B2: Daytrips / Tagestouren / Excursions.
A3: Date / Update | B3: 46195
A4: Legend | B4: Checked | C4: Changes | D4: Analysis done | E4: Analysis tbd
A6: Details for Directus Set-up | K6: Translatable? | N6: Import Details "tours" | U6: Remarks / Comments | X6: Legacy | Y6: Stakeholder Notes
A7: Special field type | B7: field_key Directus | C7: data_type | D7: interface (characters max) | E7: Relation (Sub-Collection) | F7: Label DE | G7: Label GB | H7: Label NL | I7: Info-Text (below the field) | K7: Yes / No | L7: Naming Translation-Collection | N7: fieldid Primarix | O7: parent table | U7: Remarks for DEV (field set-up and Import) | V7: Remarks + Tasks internal | X7: tbd after import | Y7: TOPS Bernd | Z7: TOPs Birgit | AA7: Notes Client
A9: Above Tabs | B9: header | C9: alias | D9: header (presentation) | F9: Header | G9: Header | H9: Header | I9: Page header above the tabs. Shows title + subtitle; no own label. | K9: No | U9: Hidden Standard (hotels): interface "header", special [alias,no-data], group: null. options.title="{{name}}", options.subtitle="{{object_id}} - {{season.season}}". Condition "Hide on create" (id _null -> hidden, clear_hidden_value_on_save).
A10: Above Tabs | B10: sell_prices_status | C10: string | D10: select-dropdown | F10: Verkaufspreis-Status | G10: Sell Prices Status | H10: Verkoopprijsstatus | I10: Tracks async sell price calculation state | K10: No | U10: hidden, root sync field
A11: Above Tabs | B11: sell_prices_updated_at | C11: timestamp | D11: datetime | F11: Aktualisiert am | G11: Sell Prices Updated At | H11: Bijgewerkt op | I11: Last successful sell price calculation | K11: No | U11: hidden, root sync field
A12: Tab-Navigation | B12: ui_tabs | C12: alias | D12: tabs | F12: - | G12: - | H12: -
A14: Tab | B14: tab_master_data | C14: alias | D14: group-raw | F14: Stammdaten | G14: Master Data | H14: Stamgegevens
A15: Block | B15: block_publication | C15: alias | D15: group-raw | F15: - | G15: - | H15: -
A16: Section (open) | B16: section_id_status | C16: alias | D16: group-detail | F16: Status & Veröffentlichung | G16: Status & Publication | H16: Status & publicatie
B17: object_id | C17: integer | D17: numerical | F17: Objekt-ID | G17: Object-ID | H17: Object-ID | I17: Automatically set. | K17: No | N17: oid | O17: tours
B18: object_info_primarix | C18: string | D18: text input | F18: Objekt Titel Primarix | G18: Object Title Primarix | H18: Objecttitel Primarix | K18: No | N18: object_info | O18: tours | U18: Non editable field
B19: season | C19: integer | D19: M2O | E19: seasons | F19: Saison-Gültigkeit | G19: Season Validity | H19: Seizoengeldigheid | K19: No | N19: season | O19: tours | U19: Transformed from "object_info": "25_" = "2025"
B20: status_primarix | C20: string | D20: dropdown | F20: Status Primarix | G20: Status Primarix | H20: Status Primarix | K20: No | N20: status (?) | O20: tours | U20: Type per Namenskonv. 4.5: string+dropdown (NOT M2O); source = freigabe (0/1) | V20: war M2O im Daytrips-Brief
B21: internal_remarks | C21: text | D21: text area | F21: Interne Hinweise | G21: Internal Remarks | H21: Interne opmerking | I21: Internal Remarks from Primarix. Consider future "Comments" feature. | K21: No | N21: field_1332_1 | O21: tours | U21: Field NOT translatable in future. Import all internal_remarks (also other languages) into this field.
B22: date_updated | C22: dateTime | D22: date | F22: Zuletzt aktualisiert | G22: Last Update | H22: Laatste update | K22: No | N22: (?) | O22: tours
B23: user_updated | C23: uuid | D23: M2O | E23: directus_users | F23: von | G23: by | H23: door | K23: No | N23: (?) | O23: tours | U23: Show last editor if possible; else "unknown".
A25: Section (open) | B25: section_botg_filter | C25: alias | D25: group-detail | F25: BOTG-Firmen-Zuordnung | G25: BOTG Company Assignment | H25: BOTG-bedrijfstoewijzing
B26: partner_visibility | C26: string | D26: radio button (all / selected) | K26: No | N26: NEW | V26: Umbenannt gem. Namenskonv. 4.6 (verbindlich): partner_type -> partner_visibility
B27: partner_selected | C27: alias | D27: M2M | E27: partner | K27: No | N27: field_1102_1 | O27: tours | U27: M2M only visible if radio != "all" (conditional). | V27: Umbenannt 4.6: partner -> partner_selected. OFFEN: Daytrips-Quelle war M2O; vehicles nutzt M2M - Kardinalitaet bestaetigen.
A29: Block | B29: block_contacts | C29: alias | D29: group-raw | F29: - | G29: - | H29: -
A30: Section (open) | B30: section_operator | C30: alias | D30: group-detail | F30: Adresse Veranstalter | G30: Operator Address | H30: Adres organisator
B31: operator_direct | C31: string | D31: radio button (Tour Operator / No Tour Operator) | F31: Veranstalter | G31: Travel Operator | H31: Reisorganisator | K31: No | N31: NEW | U31: No import (new field): "No" / "Yes". If "Yes": dropdown filtered from booking_partner. | Y31: wie Rundreisen?
B32: operator_linked | C32: integer | D32: many to one | E32: booking_partners | F32: Ausgewählter Tour Operator | G32: Chosen Tour Operator | H32: Gekozen touroperator | K32: No | N32: NEW | U32: No import (new field): dropdown with "Travel Operators" (new sub-category in booking_partners). | AA32: 07.04.: "Inbounder" könnten an Relevanz gewinnen. Ergo: Mail-Adresse erhalten (9%) + 1 Feld (Text Area) für Rest.
A34: COMMENT | B34: Following fields if radio "Direct Booking":
B35: name_operator | C35: string | D35: text input | F35: Name (Veranstalter) | G35: Name (Operator) | H35: Naam (organisator) | K35: No | N35: field_540_1 | O35: tours
B36: street | C36: string | D36: text input | F36: Straße | G36: Street | H36: Straat | K36: No | N36: field_541_1 | O36: tours
B37: street_number | C37: string | D37: text input | F37: Hausnummer | G37: Street Number | H37: Huisnummer | K37: No | N37: field_542_1 | O37: tours
B38: postcode | C38: string | D38: text input | F38: PLZ | G38: Postal Code | H38: Postcode | K38: No | N38: field_543_1 | O38: tours
B39: place | C39: string | D39: auto complete | E39: places | F39: Ort | G39: City / Town | H39: Plaats | I39: Defines further geographical details (country, state, region). | K39: No | N39: field_544_1 | O39: tours | U39: Adapt import: field is free text. Match to entry in new collection; report missing data.
B40: location_tour32 | C40: integer | D40: M2O | E40: locations_tour32 | F40: Suchort (Tour User only) | G40: Search Location (Tour User only) | H40: Zoeklocatie (Tour User only) | K40: No | N40: field_1346_1 | O40: tours | U40: Adapt import: free text -> match to collection; report missing data.
B41: state | C41: integer | D41: M2O | E41: states | F41: Staat / Bundesland | G41: State / Province | H41: Staat / Provincie | K41: No | N41: field_545_1 | O41: tours | U41: Adapt import: free text -> match to collection; report missing data.
B42: country | C42: integer | D42: M2O | E42: countries | F42: Land | G42: Country | H42: Land | I42: Defined by "Place" | K42: No | N42: field_546_1 | O42: tours | U42: Adapt import: free text -> match to collection; report missing data.
B43: postbox_number | F43: Postfach Nr | G43: PO Box No | H43: Postbus nr | N43: field_547_1 | O43: tours | U43: NOT to be imported!
B44: phone_general | C44: string | D44: phone number | F44: Telefon (allgemein) | G44: Phone (general) | H44: Telefoon (algemeen) | K44: No | N44: field_550_1 | O44: tours | V44: ggf. als repeater (json)
B45: phone_after_hours | C45: string | D45: phone number | F45: Telefon (after hours) | G45: Phone (after hours) | H45: Telefoon (na kantooruren) | K45: No | N45: field_551_1 | O45: tours | V45: Umbenannt 1.2/4.3: phone_ah -> phone_after_hours (keine Abkuerzung)
B46: fax_general | D46: - | F46: Fax (allgemein) | G46: Fax (general) | H46: Fax (algemeen) | N46: field_552_1 | O46: tours | U46: NOT to be imported!
...

Sheet #4 tours (aka roundtrips)
A1: Collection | B1: tours
A2: Remarks | B2: Rundreisen / Tours (geführte Reisen mit vordefiniertem Programm).
A3: Date / Update | B3: 46195
A4: Legend | B4: Checked | C4: Changes | D4: Analysis done | E4: Analysis tbd
A6: Details for Directus Set-up | K6: Translatable? | N6: Import Details "trips" | Q6: Import Details "studienreisen" (Karawane) | U6: Remarks / Comments | X6: Legacy | Y6: Stakeholder Notes
A7: Special field type | B7: field_key Directus | C7: data_type | D7: interface (characters max) | E7: Relation (Sub-Collection) | F7: Label DE | G7: Label GB | H7: Label NL | I7: Info-Text (below the field) | K7: Yes / No | L7: Naming Translation-Collection | N7: fieldid Primarix | O7: parent table | U7: Remarks for DEV (field set-up and Import) | V7: Remarks + Tasks internal | X7: tbd after import | Y7: TOPS Bernd | Z7: TOPs Birgit | AA7: Notes Client
A9: Above Tabs | B9: header | C9: alias | D9: header | F9: Header | G9: Header | H9: Header | I9: Page header above the tabs (title + subtitle) | K9: No
A10: Above Tabs | B10: sell_prices_status | C10: string | D10: select-dropdown | F10: Verkaufspreis-Status | G10: Sell Prices Status | H10: Verkoopprijsstatus | I10: Tracks async sell price calculation state | K10: No
A11: Above Tabs | B11: sell_prices_updated_at | C11: timestamp | D11: datetime | F11: Aktualisiert am | G11: Sell Prices Updated At | H11: Bijgewerkt op | I11: Last successful sell price calculation | K11: No
A12: Tab-Navigation | B12: ui_tabs | C12: alias | D12: tabs | F12: - | G12: - | H12: -
A14: Tab | B14: tab_master_data | C14: alias | D14: group-raw | F14: Stammdaten | G14: Master Data | H14: Stamgegevens
A15: Block | B15: block_publication | C15: alias | D15: group-raw | F15: - | G15: - | H15: -
A16: Section (open) | B16: section_publication | C16: alias | D16: group-detail | F16: Status & Veröffentlichung | G16: Status & Publication | H16: Status & publicatie
B17: object_id | C17: integer | D17: numerical | F17: Objekt-ID | G17: Object-ID | H17: Object-ID | I17: Automatically set. | K17: No | N17: oid | O17: trips
B18: object_info_primarix | C18: string | D18: text input | F18: Objekt Titel Primarix | G18: Object Title Primarix | H18: Objecttitel Primarix | K18: No | N18: object_info | O18: trips | U18: Non editable field
B19: season | C19: integer | D19: M2O | E19: seasons | F19: Saison-Gültigkeit | G19: Season Validity | H19: Seizoengeldigheid | K19: No | N19: season | O19: trips | U19: Transformed from "object_info": "25_" = "2025"
B20: status_primarix | C20: string | D20: dropdown | F20: Status Primarix | G20: Status Primarix | H20: Status Primarix | K20: No | N20: status (?) | O20: trips | U20: Type per Namenskonv. 4.5: string+dropdown (NOT M2O). | V20: war M2O im Brief
B21: internal_remarks | C21: text | D21: text area | F21: Interne Hinweise | G21: Internal Remarks | H21: Interne opmerking | I21: Internal Remarks from Primarix. Consider future "Comments" feature. | K21: No | N21: field_537_1 | O21: trips | U21: Field NOT translatable in future. Import all internal_remarks (also other languages) into this field.
B22: date_updated | C22: dateTime | D22: date | F22: Zuletzt aktualisiert | G22: Last Update | H22: Laatste update | K22: No | N22: (?) | O22: trips
B23: user_updated | C23: uuid | D23: M2O | E23: directus_users | F23: von | G23: by | H23: door | K23: No | N23: (?) | O23: trips | U23: Show last editor if possible; else "unknown".
A25: Section (open) | B25: section_botg_filter | C25: alias | D25: group-detail | F25: BOTG-Firmen-Zuordnung | G25: BOTG Company Assignment | H25: BOTG-bedrijfstoewijzing
B26: partner_visibility | C26: string | D26: radio button (all / selected) | K26: No | V26: Umbenannt 4.6: partner_type -> partner_visibility
B27: partner_selected | C27: alias | D27: M2M | E27: partner | K27: No | N27: field_1103_1 | O27: trips | U27: M2M only visible if radio != "all" (conditional). | V27: Umbenannt 4.6: partner -> partner_selected. OFFEN: Quelle war M2O; vehicles nutzt M2M - Kardinalitaet bestaetigen.
B28: is_axolot_export | C28: boolean | D28: radio | F28: Axolot-Export | G28: Axolot Export | H28: Axolot-export | N28: field_1538_1 | O28: trips | U28: "Axolot" = yes; "kein Export" = no. | V28: Umbenannt 4.3 (boolean is_): exportfilter -> is_axolot_export; ggf. allgemeiner export_channel? - Entscheidung Tommy.
A30: Block | B30: block_contacts | C30: alias | D30: group-raw | F30: - | G30: - | H30: -
A31: Section (open) | B31: section_operator | C31: alias | D31: group-detail | F31: Veranstalter | G31: Operator | H31: Organisator
B32: operator_direct | C32: string | D32: radio | F32: Veranstalter | G32: Travel Operator | H32: Reisorganisator | K32: No | N32: NEW | U32: No import (new field): "No" / "Yes". If "Yes": dropdown filtered from booking_partner.
B33: operator_linked | C33: integer | D33: many to one | E33: booking_partners | F33: Ausgewählter Tour Operator | G33: Chosen Tour Operator | H33: Gekozen touroperator | K33: No | N33: NEW | U33: No import (new field): dropdown with "Travel Operators" (new sub-category in booking_partners). | AA33: 07.04.: "Inbounder" könnten an Relevanz gewinnen. Ergo: Mail-Adresse erhalten (9%) + 1 Feld (Text Area) für Rest.
A35: COMMENT | B35: Following fields if radio "Yes":
B36: name_operator | C36: string | D36: text input | F36: Name (Veranstalter) | G36: Name (Operator) | H36: Naam (organisator) | K36: No | N36: field_493_1 | O36: trips
B37: street | C37: string | D37: text input | F37: Straße | G37: Street | H37: Straat | K37: No | N37: field_494_1 | O37: trips
B38: street_number | C38: string | D38: text input | F38: Hausnummer | G38: Street Number | H38: Huisnummer | K38: No | N38: field_495_1 | O38: trips
B39: postcode | C39: string | D39: text input | F39: PLZ | G39: Postal Code | H39: Postcode | K39: No | N39: field_496_1 | O39: trips
B40: place | C40: string | D40: auto complete | E40: places | F40: Ort | G40: City / Town | H40: Plaats | I40: Defines further geographical details (country, state, region). | K40: No | N40: field_497_1 | O40: trips | U40: Adapt import: free text -> match to collection; report missing data.
B41: location_tour32 | C41: integer | D41: M2O | E41: locations_tour32 | F41: Suchort (Tour User only) | G41: Search Location (Tour User only) | H41: Zoeklocatie (Tour User only) | K41: No | N41: field_1345_1 | O41: trips | U41: Adapt import: free text -> match to collection; report missing data.
B42: country | C42: integer | D42: M2O | E42: countries | F42: Land | G42: Country | H42: Land | I42: Defined by "Place" | K42: No | N42: field_499_1 | O42: trips | U42: Adapt import: free text -> match to collection; report missing data.
B43: postbox_number | F43: Postfach Nr | G43: PO Box No | H43: Postbus nr | N43: field_500_1 | O43: trips | V43: OFFEN: im Brief 3x identischer key/field_500 - Duplikate klaeren. | Y43: Erhalten od. weg?
B44: state | C44: integer | D44: M2O | E44: states | F44: Staat / Bundesland | G44: State / Province | H44: Staat / Provincie | K44: No | N44: field_498_1 | O44: trips | U44: Adapt import: free text -> match to collection; report missing data.
B45: phone_general | C45: string | D45: phone number | F45: Telefon (allgemein) | G45: Phone (general) | H45: Telefoon (algemeen) | K45: No | N45: field_503_1 | O45: trips | V45: ggf. als repeater (json)
B46: phone_after_hours | C46: string | D46: phone number | F46: Telefon (after hours) | G46: Phone (after hours) | H46: Telefoon (na kantooruren) | K46: No | N46: field_219_1 | O46: trips | V46: Umbenannt 4.3: phone_ah -> phone_after_hours
...

Sheet #5a rental_companies
A1: Collection | B1: rental_companies
A2: Remarks | B2: M20-collection for "vehicles". Data to be imported ONCE (!) from "rentalcars" and afterwards "camper". Companies and its data will exist more than once. Choose the data set with latest change date!
A3: Date / Update | B3: 46189
A5: Legend | B5: Checked | C5: Changes | D5: Analysis done | E5: Analysis tbd | F5: Hidden field. | G5: Legacy fields not imported.
A7: Details for Directus Set-up | K7: Translatable? | N7: Import Details "rentalcars" | Q7: Import Details "campers" | U7: Remarks / Comments | X7: Legacy | Z7: TOPS Bernd | AA7: TOPs Birgit | AB7: Notes Client
A8: Special field type | B8: field_key Directus | C8: data_type | D8: interface (characters max) | E8: Relation (Sub-Collection) | F8: Label DE | G8: Label GB | H8: Label NL | I8: Info-Text (below the field) | K8: Yes / No | L8: Naming Translation-Collection | N8: fieldid Primarix | O8: parent table | Q8: fieldid Primarix | R8: parent table | S8: field id | U8: Remarks for DEV (field set-up and Import) | V8: Remarks + Tasks internal | X8: Kill after import
A10: Above Tabs | B10: header | C10: alias | D10: header | F10: Header | G10: Header | H10: Header | I10: Page header above the tabs (title + subtitle) | K10: No
A11: Above Tabs | B11: sell_prices_status | C11: string | D11: select-dropdown | F11: Verkaufspreis-Status | G11: Sell Prices Status | H11: Verkoopprijsstatus | I11: Tracks async sell price calculation state | K11: No
A12: Above Tabs | B12: sell_prices_updated_at | C12: timestamp | D12: datetime | F12: Aktualisiert am | G12: Sell Prices Updated At | H12: Bijgewerkt op | I12: Last successful sell price calculation | K12: No
A13: Tab-Navigation | B13: ui_tabs | C13: alias | D13: tabs | F13: - | G13: - | H13: -
A15: Tab | B15: tab_master_data | C15: alias | D15: group-raw | F15: Stammdaten | G15: Master Data | H15: Stamgegevens
A16: Block | B16: block_publication | C16: alias | D16: group-raw | F16: - | G16: - | H16: -
A17: Section (open) | B17: section_publication | C17: alias | D17: group-detail | F17: Status & Veröffentlichung | G17: Status & Publication | H17: Status & publicatie
B18: object_id | C18: integer | D18: numerical | F18: Objekt-ID | G18: Object-ID | H18: Object-ID | K18: No | N18: oid | O18: rentalcars | Q18: oid | R18: campers | S18: object_id
A19: Field hidden | B19: object_info_primarix | C19: string | D19: text input | F19: Objekt Titel Primarix | G19: Object Title Primarix | H19: Objecttitel Primarix | K19: No | N19: object_info | O19: rentalcars | Q19: object_info | R19: campers | S19: object_info_primarix | U19: Non editable field | Z19: Angebots-Name
B20: season | C20: integer | D20: M2O | E20: seasons | F20: Saison-Gültigkeit | G20: Season Validity | H20: Seizoengeldigheid | K20: No | N20: season | O20: rentalcars | Q20: season | R20: campers | S20: season | U20: Transformed value from "object info": "25_" = "2025"
B21: status_primarix | C21: string | D21: dropdown | F21: Status Primarix | G21: Status Primarix | H21: Status Primarix | K21: No | N21: freigabe | O21: rentalcars | Q21: freigabe | R21: camper | S21: status_primarix
B22: internal_remarks | C22: text | D22: text area | F22: Interne Hinweise | G22: Internal Remarks | H22: Interne opmerking | I22: Internal Remarks from Primarix. - Please consider for the future the "Comments"-Feature (Icon on right side). | K22: No | N22: field_1331_1 | O22: rentalcars | Q22: field_1330_1 | R22: campers | S22: internal_remarks | U22: IMPORTANT: The field is in future NOT translatable. Within the import you need all "internal_remarks" into this field (also from other languages).
A23: Field hidden | B23: date_updated | C23: dateTime | D23: date | F23: Zuletzt aktualisiert | G23: Last Update | H23: Laatste update | K23: No | N23: lastupdate | O23: rentalcars | Q23: lastupdate | R23: camper | S23: date_updated
A24: Field hidden | B24: user_updated | C24: uuid | D24: M2O | E24: directus_users | F24: von | G24: by | H24: door | K24: No | N24: — | O24: — | Q24: — | R24: — | S24: user_updated | U24: Pls show the last editor if possible (in case information is not available in Primarix show "unknown" or similar)
A26: Section (closed) | B26: section_botg_companies | C26: alias | D26: group-detail | F26: BOTG-Firmen-Zuordnung | G26: BOTG Company Assignment | H26: BOTG-bedrijfstoewijzing
B27: partner_visibility | C27: string | D27: radio button (all / selected) | K27: No | N27: NEW | Q27: NEW | S27: partner_type
B28: partner_selected | C28: alias | D28: M2M | E28: partner | K28: No | N28: field_1104_1 | O28: rentalcars | Q28: field_1105_1 | R28: campers | S28: partner
A30: Block | B30: block_contacts | C30: alias | D30: group-raw | F30: - | G30: - | H30: -
A31: Section (open) | B31: section_address | C31: alias | D31: group-detail | F31: Adresse Vermieter | G31: Address Rental Company | H31: Adres verhuurder
B32: name_company | C32: string | D32: text input | F32: Name (Vermieter) | G32: Name (Rental Company) | H32: Naam (Verhuurder) | K32: No | N32: field_425_1 | O32: rentalcars | Q32: field_268_1 | R32: camper | S32: name
B33: rental_type | C33: string | D33: radio button | F33: Vermietete Fahrzeugarten | G33: Rented Vehicle Types | H33: Verhuurde voertuigtypes | K33: No | N33: NEW | Q33: - | R33: - | S33: - | U33: "Campers", "Rental Cars"
B34: street | C34: string | D34: text input | F34: Straße | G34: Street | H34: Straat | K34: No | N34: field_426_1 | O34: rentalcars | Q34: field_269_1 | R34: camper | S34: street
B35: street_number | C35: string | D35: text input | F35: Hausnummer | G35: Street Number | H35: Huisnummer | K35: No | N35: field_427_1 | O35: rentalcars | Q35: field_270_1 | R35: camper | S35: street_number
B36: zip_code | C36: string | D36: text input | F36: PLZ | G36: Postal Code | H36: Postcode | K36: No | N36: field_428_1 | O36: rentalcars | Q36: field_272_1 | R36: camper | S36: zip_code
B37: place | C37: integer | D37: auto complete | E37: places | F37: Ort | G37: City / Town | H37: Plaats | K37: No | N37: field_429_1 | O37: rentalcars | Q37: field_274_1 | R37: camper | S37: place | U37: Adapt import: Actually field contains text inputs. Match to entry in new collection. Report missing data separatly!
B38: location_tour32 | C38: integer | D38: M2O | E38: locations_tour32 | F38: Suchort (Tour User only) | G38: Search Location (Tour User only) | H38: Zoeklocatie (Tour User only) | K38: No | N38: field_1344_1 | O38: rentalcars | Q38: field_1343_1 | R38: camper | S38: location_tour32 | U38: Adapt import: Actually field contains text inputs. Match to entry in new collection. Report missing data separatly!
B39: country | C39: integer | D39: M2O | E39: countries | F39: Land | G39: Country | H39: Land | K39: No | N39: field_431_1 | O39: rentalcars | Q39: field_276_1 | R39: camper | S39: country | U39: Adapt import: Actually field contains text inputs. Match to entry in new collection. Report missing data separatly!
F40: Postfach Nr | N40: field_432_1 | O40: rentalcars | Q40: field_271_1 | R40: camper | S40: postbox_number | Z40: Erhalten od. weg?
F41: Postfach PLZ | N41: field_433_1 | O41: rentalcars | Q41: field_273_1 | R41: camper | S41: postbox_zip_code | Z41: Erhalten od. weg?
F42: Postfach Ort | N42: field_434_1 | O42: rentalcars | Q42: field_385_1 | R42: camper | S42: postbox_town | Z42: Erhalten od. weg?
B43: state | C43: integer | D43: M2O | E43: states | F43: Staat / Bundesland | G43: State / Province | H43: Staat / Provincie | K43: No | N43: field_430_1 | O43: rentalcars | Q43: field_275_1 | R43: camper | S43: state | U43: Adapt import: Actually field contains text inputs. Match to entry in new collection. Report missing data separatly!
B44: phone_general | C44: string | D44: phone number | F44: Telefon (allgemein) | G44: Phone (general) | H44: Telefoon (algemeen) | K44: No | N44: field_435_1 | O44: rentalcars | Q44: field_277_1 | R44: camper | S44: phone_general | V44: ggf. als "repeater (json)"
B45: phone_after_hours | C45: string | D45: phone number | F45: Telefon (after hours) | G45: Phone (after hours) | H45: Telefoon (na kantooruren) | K45: No | N45: field_436_1 | O45: rentalcars | Q45: field_386_1 | R45: camper | S45: phone_ah
D46: - | F46: Fax (allgemein) | G46: Fax (General) | H46: Fax (algemeen) | N46: field_437_1 | O46: rentalcars | Q46: field_278_1 | R46: camper | S46: fax_general | U46: NOT to be imported!
...

Sheet #5b rental_depots
A1: Collection | B1: rental_depots
A2: Remarks | B2: M20-collection for "vehicles". Data to be imported ONCE (!) from "rentalcars" and afterwards "camper". Companies and its data will exist more than once. Choose the data set with latest change date!
A3: Date / Update | B3: 46189
A5: Legend | B5: Checked | C5: Changes | D5: Analysis done | E5: Analysis tbd
A7: Details for Directus Set-up | K7: Translatable? | N7: Import Details "rentalcars" | Q7: Import Details "campers" | U7: Remarks / Comments | X7: Legacy
A8: Special field type | B8: field_key Directus | C8: data_type | D8: interface (characters max) | E8: Relation (Sub-Collection) | F8: Label DE | G8: Label GB | H8: Label NL | I8: Info-Text (below the field) | K8: Yes / No | L8: Naming Translation-Collection | N8: fieldid Primarix | O8: parent table | Q8: fieldid Primarix | R8: parent table | S8: field id | U8: Remarks for DEV (field set-up and Import) | V8: Remarks + Tasks internal | X8: Kill after import
A10: Above Tabs | B10: header | C10: alias | D10: header | F10: Header | G10: Header | H10: Header | I10: Page header above the tabs (title + subtitle) | K10: No
A11: Tab-Navigation | B11: ui_tabs | C11: alias | D11: tabs | F11: - | G11: - | H11: -
A13: Tab | B13: tab_master_data | C13: alias | D13: group-raw | F13: Stammdaten | G13: Master Data | H13: Stamgegevens
A14: Section (open) | B14: section_publication | C14: alias | D14: group-detail | F14: Status & Veröffentlichung | G14: Status & Publication | H14: Status & publicatie
B15: object_id | C15: integer | D15: numerical | F15: Objekt-ID | G15: Object-ID | H15: Object-ID | K15: No | N15: oid | O15: rentalcars_depots | Q15: oid | R15: campers | S15: object_id
B16: status_primarix | C16: string | D16: dropdown | F16: Status Primarix | G16: Status Primarix | H16: Status Primarix | K16: No | N16: status (?) | O16: rentalcars_depots | Q16: status (?) | R16: campers | S16: status_primarix
B17: date_updated | C17: dateTime | D17: date | F17: Zuletzt aktualisiert | G17: Last Update | H17: Laatste update | K17: No | N17: (?) | O17: rentalcars_depots | Q17: (?) | R17: campers | S17: date_updated
B18: user_updated | C18: uuid | D18: M2O | E18: directus_users | F18: von | G18: by | H18: door | K18: No | N18: (?) | O18: rentalcars_depots | Q18: (?) | R18: campers | S18: user_updated | U18: Pls show the last editor if possible (in case information is not available in Primarix show "unknown" or similar)
A20: Section (open) | B20: section_depot_details | C20: alias | D20: group-detail | F20: Depot-Daten | G20: Depot Details | H20: Depotgegevens
B21: name_depot | C21: string | D21: text input | F21: Name (Depot) | G21: Name (Depot) | H21: Naam (Depot) | K21: No | N21: field_1245_1 | O21: rentalcars_depots | Q21: field_409_1 | R21: camper_depots | S21: name_depot
A22: Field hidden | B22: depots | C22: alias | D22: M2M | F22: Depots | G22: Depots | H22: Depots | K22: No | N22: field_1327_1 | O22: rentalcars_depots | Q22: field_1024_1 | R22: camper | S22: depots | U22: Legacy import only – not actively used
B23: rental_company | C23: integer | D23: M2O | E23: rental_companies | F23: Vermieter | G23: Rental Company | H23: Verhuurder | K23: No | N23: NEW | Q23: NEW | U23: OID of Rental Company
B24: category | C24: integer | D24: M2O | E24: rental_depot_categories | F24: Kategorie Mietstation | G24: Depot Category | H24: Depotcategorie | K24: No | N24: NEW | Q24: NEW | U24: Import "solved" within by set-up of "rental_companies"
B25: rental_zone | C25: integer | D25: M2O | E25: vehicles_rental_zones | F25: Miet–Zone (Region) | G25: Rental Zone (Region) | H25: Huurzone (regio) | K25: No | N25: field_1246_1 | O25: rentalcars_depots | Q25: - | R25: - | S25: rental_zone | V25: Aktuell 4 Zonen in AUT.
B26: street | C26: string | D26: text input | F26: Straße | G26: Street | H26: Straat | K26: No | N26: field_1247_1 | O26: rentalcars_depots | Q26: field_410_1 | R26: camper_depots | S26: depot_street
B27: street_number | C27: string | D27: text input | F27: Hausnummer | G27: Street Number | H27: Huisnummer | K27: No | N27: field_1248_1 | O27: rentalcars_depots | Q27: field_411_1 | R27: camper_depots | S27: depot_street_number
B28: zip_code | C28: string | D28: text input | F28: PLZ | G28: Postal Code | H28: Postcode | K28: No | N28: field_1249_1 | O28: rentalcars_depots | Q28: field_412_1 | R28: camper_depots | S28: depot_zip_code | U28: Define as non-editable field. In case of editing in Directus the flag is being set automatically.
B29: place | C29: integer | D29: M2O | E29: places | F29: Ort | G29: City / Town | H29: Plaats | K29: No | N29: field_1250_1 | O29: rentalcars_depots | Q29: field_413_1 | R29: camper_depots | S29: depot_town
B30: state | C30: integer | D30: M2O | E30: states | F30: Bundesland | G30: State / Province | H30: Staat / Provincie | K30: No | N30: field_1251_1 | O30: rentalcars_depots | Q30: field_414_1 | R30: camper_depots | S30: depot_state
B31: country | C31: integer | D31: M2O | E31: countries | F31: Land | G31: Country | H31: Land | K31: No | N31: field_1252_1 | O31: rentalcars_depots | Q31: field_415_1 | R31: camper_depots | S31: depot_country
B32: phone_general | C32: string | D32: phone number | F32: Telefon (allgemein) | G32: Phone | H32: Telefoon | K32: No | N32: field_1253_1 | O32: rentalcars_depots | Q32: field_416_1 | R32: camper_depots | S32: depot_phone
B33: fax | D33: - | F33: Fax (allgemein) | N33: field_1254_1 | O33: rentalcars_depots | Q33: field_417_1 | R33: camper_depots | S33: fax
B34: email | C34: string | D34: mail | F34: E-Mail | G34: Email | H34: E-mail | K34: No | N34: field_1255_1 | O34: rentalcars_depots | Q34: field_418_1 | R34: camper_depots | S34: depot_email
B35: surcharge | C35: text | D35: text area | F35: Depot–Zuschlag (for web use) | G35: Depot surcharge (for web use) | H35: Depottoeslag (for web use) | N35: field_1256_1 | O35: rentalcars_depots | Q35: field_1091_1 | R35: camper_depots | S35: depot_surcharge
B36: office_hours_deviating | C36: text | D36: text area | F36: Abweichende Öffnungszeiten | G36: Deviating Opening Hours | H36: Afwijkende openingstijden | K36: Yes | L36: rental_depots_translations | N36: NEW | Q36: field_1403_1 | R36: camper_depots | S36: depot_office_hours_deviating | V36: Öffnungszeiten werden aktuell unter Vermieter "global" gepflegt.
A39: NOTE: | B39: No Image Badge, Media etc.

Sheet #5c vehicles
A1: Collection | B1: vehicles
A2: Remarks | B2: M20-collection for "vehicles". Dat to be imported ONCE (!) from "rentalcars" and aftewardd "camper". Companies and ist data will exist more than once. Choose the data set with latest change data!
A3: Date / Update | B3: 46189
A4: Legend | B4: Checked | C4: Changes | D4: Analysis done | E4: Analysis tbd
A6: Details for Directus Set-up | K6: Translatable? | N6: Import Details "rentalcars" | Q6: Import Details "campers" | U6: Remarks / Comments | X6: Legacy
A7: Special field type | B7: field_key Directus | C7: data_type | D7: interface (characters max) | E7: Relation (Sub-Collection) | F7: Label DE | G7: Label GB | H7: Label NL | I7: Info-Text (below the field) | K7: Yes / No | L7: Naming Translation-Collection | N7: fieldid Primarix | O7: parent table | Q7: fieldid Primarix | R7: parent table | S7: field id | U7: Remarks for DEV (field set-up and Import) | V7: Remarks + Tasks internal | X7: Kill after import
A9: Above Tabs | B9: header | C9: alias | D9: header | F9: Header | G9: Header | H9: Header | I9: Page header above the tabs (title + subtitle) | K9: No
A10: Tab-Navigation | B10: ui_tabs | C10: alias | D10: tabs | F10: - | G10: - | H10: -
A12: Tab | B12: tab_master_data | C12: alias | D12: group-raw | F12: Stammdaten | G12: Master Data | H12: Stamgegevens
A13: Block | B13: block_publication | C13: alias | D13: group-raw | F13: - | G13: - | H13: -
A14: Section (open) | B14: section_publication | C14: alias | D14: group-detail | F14: Status & Veröffentlichung | G14: Status & Publication | H14: Status & publicatie
B15: object_id | C15: integer | D15: numerical | F15: Objekt-ID | G15: Object-ID | H15: Object-ID | K15: No | N15: oid | O15: rentalcars_vehicle | Q15: oid | R15: campers | S15: object_id
B16: status_primarix | C16: string | D16: dropdown | F16: Status Primarix | G16: Status Primarix | H16: Status Primarix | K16: No | N16: status (?) | O16: rentalcars_vehicle | Q16: status (?) | R16: campers | S16: status_primarix
B17: date_updated | C17: dateTime | D17: date | F17: Zuletzt aktualisiert | G17: Last Update | H17: Laatste update | K17: No | N17: (?) | O17: rentalcars_vehicle | Q17: (?) | R17: campers | S17: date_updated
B18: user_updated | C18: uuid | D18: M2O | E18: directus_users | F18: von | G18: by | H18: door | K18: No | N18: (?) | O18: rentalcars_vehicle | Q18: (?) | R18: campers | S18: user_updated | U18: Pls show the last editor if possible (in case information is not available in Primarix show "unknown" or similar)
A20: Section (closed) | B20: section_botg_companies | C20: alias | D20: group-detail | F20: BOTG-Firmen-Zuordnung | G20: BOTG Company Assignment | H20: BOTG-bedrijfstoewijzing
B21: partner_visibility | C21: string | D21: radio button (all / selected) | K21: No | N21: NEW | Q21: NEW | S21: partner_type | U21: Default: "all"
B22: partner_selected | C22: alias | D22: M2M | E22: partner | K22: No | N22: field_1104_1 | O22: rentalcars | Q22: field_1105_1 | R22: campers | S22: partner
A24: Block | B24: block_vehicle_basics | C24: alias | D24: group-raw | F24: - | G24: - | H24: -
A25: Section (open) | B25: section_type_company | C25: alias | D25: group-detail | F25: Typ & Vermieter | G25: Type & Company | H25: Type & verhuurder
B26: rental_type | C26: string | D26: radio | F26: Typ | G26: Type | H26: Type | K26: No | N26: NEW | Q26: NEW | S26: rental_type | U26: "Car" or "Camper"
B27: name_vehicle | C27: string | D27: text input | F27: Name (Fahrzeug) | G27: Name (Vehicle) | H27: Naam (voertuig) | K27: No | N27: field_1033_1 | O27: rentalcars_vehicle | Q27: field_259_1 | R27: camper_vehicle | S27: vehicle_title
B28: rental_company | C28: integer | D28: M2O | E28: rental_companies | F28: Vermieter | G28: Rental Company | H28: Verhuurder | K28: No | N28: NEW | Q28: NEW | S28: rental_company | U28: OID of Rental Company
B29: category | C29: integer | D29: many to one | E29: vehicle_categories | F29: Fahrzeugkategorie | G29: Vehicle Category | H29: Voertuigcategorie | K29: No | N29: field_465_1 | O29: rentalcars_vehicle | Q29: - | R29: -
B30: supplier_product_code | C30: string | D30: text input | F30: Buchungscode Supplier | G30: Supplier Booking Code | H30: Supplier boekingscode | K30: No | N30: field_866_1 | O30: rentalcars_vehicle | Q30: field_877_1 | R30: camper_vehicle | S30: vehicle_supplier_product_code
B31: depot_availability | C31: string | D31: radio button (all / selected) | F31: Wagen an allen Depots verfügbar | G31: Available at all depots | H31: Beschikbaar op alle depots | K31: No | N31: NEW | Q31: NEW | U31: rentalcars: default "true"; campers: default "false"
B32: depots_selected | C32: alias | D32: M2M | E32: rental_depots | F32: Verfügbar an folgenden Stationen | G32: Available at the following stations | H32: Beschikbaar op de volgende stations | K32: No | N32: - | O32: - | Q32: field_1068_1 | R32: camper_vehicle | S32: depots_available
A34: Tab | B34: tab_description | C34: alias | D34: group-raw | F34: Beschreibung | G34: Description | H34: Beschrijving
A35: Section (open) | B35: section_attributes | C35: alias | D35: group-detail | F35: Merkmale | G35: Attributes | H35: Kenmerken
B36: drive_type | C36: string | D36: radio (2wd / 4wd) | F36: Antriebsart | G36: Drive type | H36: Aandrijving | K36: No | N36: field_1063_1 | O36: rentalcars_vehicle | Q36: field_1054_1 | R36: camper_vehicle | S36: drive_type
B37: persons_max | C37: integer | D37: numeric (1-6) | F37: Anzahl Personen maximal | G37: Maximum number of persons | H37: Maximaal aantal personen | K37: No | N37: field_1440_1 | O37: rentalcars_vehicle | Q37: field_1053_1 | R37: camper_vehicle | S37: vehicle_persons_max
B38: suitcase_big | C38: integer | D38: numerical | F38: Koffer groß | G38: Large suitcase | H38: Grote koffer | K38: No | N38: field_1441_1 | O38: rentalcars_vehicle | Q38: - | R38: - | S38: vehicle_suitcase_big
B39: suitcase_small | C39: integer | D39: numerical | F39: Koffer klein | G39: Small suitcase | H39: Kleine koffer | K39: No | N39: field_1442_1 | O39: rentalcars_vehicle | Q39: - | R39: - | S39: vehicle_suitcase_small
A41: Section (open) | B41: section_descriptions | C41: alias | D41: group-detail | F41: Beschreibungstexte | G41: Descriptions | H41: Beschrijvingen
B42: subline | C42: string | D42: text input | F42: Subline Fahrzeug | G42: Vehicle subline | H42: Voertuig subline | K42: Yes | L42: vehicles_descriptions_translations | N42: NEW | O42: - | Q42: field_260_1 | R42: camper_vehicle | S42: vehicle_subline
B43: teaser | C43: text | D43: text area | F43: Einleitungstext | G43: Introduction text | H43: Inleidende tekst | K43: Yes | L43: vehicles_descriptions_translations | N43: NEW | O43: - | Q43: field_261_1 | R43: camper_vehicle | S43: vehicle_teaser
B44: description | C44: text | D44: text area | F44: Fahrzeugbeschreibung | G44: Vehicle description | H44: Voertuigbeschrijving | K44: Yes | L44: vehicles_descriptions_translations | N44: field_466_1 | O44: rentalcars_vehicle | Q44: field_262_1 | R44: camper_vehicle | S44: vehicle_description
B45: equipment | C45: text | D45: text area | F45: Fahrzeugausstattung | G45: Vehicle equipment | H45: Voertuiguitrusting | K45: Yes | L45: vehicles_descriptions_translations | N45: field_899_1 | O45: rentalcars_vehicle | Q45: field_264_1 | R45: camper_vehicle | S45: vehicle_equipment
B46: bond | C46: text | D46: text area | F46: Abweichende Kautionsbdeingungen | G46: Additional notes | H46: Overige opmerkingen | I46: Warnungen od. andere Hinweise. | K46: Yes | L46: vehicles_descriptions_translations | N46: field_902_1 | O46: rentalcars_vehicle | Q46: - | R46: - | S46: bond
D47: - | G47: URL alias | H47: URL-alias | N47: - | Q47: field_1460_1 | R47: camper_vehicle
...

Sheet #5d camper_specs
A1: Collection | B1: camper_specs
A2: Remarks | B2: Sub-collection (O2O to vehicles, only rental_type=Camper). Source: Dreamtime factsheets + camper_vehicle.
A3: Date / Update | B3: 46189
A4: Legend | B4: Checked | C4: Changes | D4: Analysis done | E4: Analysis tbd
A6: Details for Directus Set-up | K6: Translatable? | N6: Import Details "rentalcars" | Q6: Import Details "campers" | U6: Remarks / Comments | X6: Legacy
A7: Special field type | B7: field_key Directus | C7: data_type | D7: interface (characters max) | E7: Relation (Sub-Collection) | F7: Label DE | G7: Label GB | H7: Label NL | I7: Info-Text (below the field) | K7: Yes / No | L7: Naming Translation-Collection | N7: fieldid Primarix | O7: parent table | Q7: fieldid Primarix | R7: parent table | S7: field id | U7: Remarks for DEV (field set-up and Import) | V7: Remarks + Tasks internal | X7: Kill after import
A9: Above Tabs | B9: header | C9: alias | D9: header | F9: Header | G9: Header | H9: Header | I9: Page header above the tabs (title + subtitle) | K9: No
A10: Tab-Navigation | B10: ui_tabs | C10: alias | D10: tabs | F10: - | G10: - | H10: -
A12: Tab | B12: tab_master_data | C12: alias | D12: group-raw | F12: Stammdaten | G12: Master Data | H12: Stamgegevens
A13: Section (open) | B13: section_status_relation | C13: alias | D13: group-detail | F13: Status & Relation | G13: Status & Relation | H13: Status & relatie
B14: vehicle | C14: integer | D14: O2O | E14: vehicles | F14: Fahrzeug | G14: Vehicle | H14: Voertuig | K14: No | Q14: NEW | R14: - | S14: vehicle | U14: Owner relation to vehicles (O2O; only rental_type=Camper)
B15: date_updated | C15: dateTime | D15: datetime | F15: Zuletzt aktualisiert | G15: Last Updated | H15: Laatst bijgewerkt | K15: No | S15: date_updated | U15: Directus standard
B16: user_updated | C16: uuid | D16: M2O | E16: directus_users | F16: von | G16: by | H16: door | K16: No | S16: user_updated | U16: Directus standard
A18: Tab | B18: tab_technical_data | C18: alias | D18: group-raw | F18: Technische Daten | G18: Technical Data | H18: Technische gegevens
A19: Section | B19: section_dimensions | C19: alias | D19: group-detail | F19: Maße & Kapazität | G19: Dimensions & Capacity | H19: Afmetingen & capaciteit
B20: berths_adults | C20: integer | D20: numerical | F20: Schlafplätze (Erw.) | G20: Berths (Adults) | H20: Slaapplaatsen (volw.) | K20: No | Q20: NEW | R20: Dreamtime | S20: berths_adults
